Workbook
Name gr: DCF!$D$16
Name term: DCF!$D$16
Name terminal: DCF!$D$16
Name tgr: DCF!$D$16
Name wacc: DCF!$D$15

Sheet 3_Statement_Model
A1: $ in millions | D1: Actuals
I2: Projections
D3: 2021 | E3: 2022 | F3: =G3-1 -> 2023 | G3: =H3-1 -> 2024 | H3: 2025 | I3: =H3+1 -> 2026 | J3: =I3+1 -> 2027 | K3: =J3+1 -> 2028 | L3: =K3+1 -> 2029 | M3: =L3+1 -> 2030
B4: x | C4: Income Statement
C6: Revenue | D6: 195929 | E6: 226954 | F6: 242290 | G6: 254453 | H6: 275235 | I6: =H6*(1+I20) -> 293533.23 | J6: =I6*(1+J20) -> 313047.96 | K6: =J6*(1+K20) -> 333860.07 | L6: =K6*(1+L20) -> 356055.82 | M6: =L6*(1+M20) -> 379727.19
C7: Cost of Goods Sold | D7: -170684 | E7: -199382 | F7: -212586 | G7: -222358 | H7: -239886 | I7: =-(1-I21)*I6 -> -256171.53 | J7: =-(1-J21)*J6 -> -273202.37 | K7: =-(1-K21)*K6 -> -291365.46 | L7: =-(1-L21)*L6 -> -310736.08 | M7: =-(1-M21)*M6 -> -331394.49
C8: Operating Expenses | D8: -18537 | E8: -19779 | F8: -21590 | G8: -22810 | H8: -24966 | I8: =-I6*I22 -> -26469.537 | J8: =-J6*J22 -> -28229.29 | K8: =-K6*K22 -> -30106.035 | L8: =-L6*L22 -> -32107.55 | M8: =-M6*M22 -> -34242.13
C9: Operating Profit | D9: =SUM(D6:D8) -> 6708 | E9: =SUM(E6:E8) -> 7793 | F9: =SUM(F6:F8) -> 8114 | G9: =SUM(G6:G8) -> 9285 | H9: =SUM(H6:H8) -> 10383 | I9: =SUM(I6:I8) -> 10892.162 | J9: =SUM(J6:J8) -> 11616.297 | K9: =SUM(K6:K8) -> 12388.573 | ... M9: =SUM(M6:M8) -> 14090.568
C11: Interest Income | D11: 143 | E11: 205 | F11: 533 | G11: 624 | H11: 589 | I11: =I33*H37 -> 650.59947 | J11: =J33*I37 -> 886.23345 | K11: =K33*J37 -> 1173.6941 | L11: =L33*K37 -> 1501.0419 | M11: =M33*L37 -> 1875.7767
C12: Interest Expense | D12: -171 | E12: -158 | F12: -160 | G12: -169 | H12: -154 | I12: =I32*SUM(I58:I59) -> -162.88686 | J12: =J32*SUM(J58:J59) -> -162.88686 | K12: =K32*SUM(K58:K59) -> -162.88686 | L12: =L32*SUM(L58:L59) -> -162.88686 | M12: =M32*SUM(M58:M59) -> -162.88686
C13: Pretax Profit | D13: =D9+D11+D12 -> 6680 | E13: =E9+E11+E12 -> 7840 | F13: =F9+F11+F12 -> 8487 | G13: =G9+G11+G12 -> 9740 | H13: =H9+H11+H12 -> 10818 | I13: =I9+I11+I12 -> 11379.874 | J13: =J9+J11+J12 -> 12339.643 | K13: =K9+K11+K12 -> 13399.381 | ... M13: =M9+M11+M12 -> 15803.458
C15: Tax Expense | D15: -1601 | E15: -1925 | F15: -2195 | G15: -2373 | H15: -2719 | I15: =-I23*I13 -> -2858.6461 | J15: =-J23*J13 -> -3099.7418 | K15: =-K23*K13 -> -3365.9499 | L15: =-L23*L13 -> -3655.0751 | M15: =-M23*M13 -> -3969.8588
C16: Net Income | D16: =D13+D15 -> 5079 | E16: =E13+E15 -> 5915 | F16: =F13+F15 -> 6292 | G16: =G13+G15 -> 7367 | H16: =H13+H15 -> 8099 | I16: =I13+I15 -> 8521.2283 | J16: =J13+J15 -> 9239.9013 | K16: =K13+K15 -> 10033.431 | ... M16: =M13+M15 -> 11833.6
C19: Margins / Growth Rates
C20: Revenue Growth Rate | E20: =E6/D6-1 -> 0.15834818 | F20: =F6/E6-1 -> 0.067573165 | G20: =G6/F6-1 -> 0.050200173 | H20: =H6/G6-1 -> 0.081673236 | I20: =AVERAGE(F20:H20) -> 0.066482191 | J20: =I20 -> 0.066482191 | K20: =J20 -> 0.066482191 | L20: =K20 -> 0.066482191 | M20: =L20 -> 0.066482191
C21: Gross Profit Margin | D21: =1+D7/D6 -> 0.12884769 | E21: =1+E7/E6 -> 0.12148717 | F21: =1+F7/F6 -> 0.12259689 | G21: =1+G7/G6 -> 0.12613331 | H21: =1+H7/H6 -> 0.12843207 | I21: =AVERAGE(G21:H21) -> 0.12728269 | J21: =I21 -> 0.12728269 | K21: =J21 -> 0.12728269 | L21: =K21 -> 0.12728269 | M21: =L21 -> 0.12728269
C22: Operating Expense as % of Revenue | D22: =-D8/D6 -> 0.094610803 | E22: =-E8/E6 -> 0.087149819 | F22: =-F8/F6 -> 0.089108094 | G22: =-G8/G6 -> 0.089643274 | H22: =-H8/H6 -> 0.09070794 | I22: =AVERAGE(G22:H22) -> 0.090175607 | J22: =I22 -> 0.090175607 | K22: =J22 -> 0.090175607 | L22: =K22 -> 0.090175607 | M22: =L22 -> 0.090175607
C23: Tax Rate | D23: =-D15/D13 -> 0.23967066 | E23: =-E15/E13 -> 0.24553571 | F23: =-F15/F13 -> 0.25863085 | G23: =-G15/G13 -> 0.2436345 | H23: =-H15/H13 -> 0.25134036 | I23: =AVERAGE(F23:H23) -> 0.2512019 | J23: =I23 -> 0.2512019 | K23: =J23 -> 0.2512019 | L23: =K23 -> 0.2512019 | M23: =L23 -> 0.2512019
C24: Memo: COGS Growth Rate | E24: =E7/D7-1 -> 0.16813527 | F24: =F7/E7-1 -> 0.066224634 | G24: =G7/F7-1 -> 0.045967279 | H24: =H7/G7-1 -> 0.078827836 | I24: =I7/H7-1 -> 0.067888611 | J24: =J7/I7-1 -> 0.066482191 | K24: =K7/J7-1 -> 0.066482191 | L24: =L7/K7-1 -> 0.066482191 | M24: =M7/L7-1 -> 0.066482191
C26: Memo: Depreciation in opex and COGS | D26: -1781 | E26: -1900 | F26: -2077 | G26: -2237 | H26: -2426 | I26: =H26*(1+I20) -> -2587.2858 | J26: =I26*(1+J20) -> -2759.2942 | K26: =J26*(1+K20) -> -2942.7382 | L26: =K26*(1+L20) -> -3138.3778 | M26: =L26*(1+M20) -> -3347.0241
C27: Memo: Capex | D27: -3588 | E27: -3891 | F27: -4323 | G27: -4710 | H27: -5498 | I27: =H27*(1+I20) -> -5863.5191 | J27: =I27*(1+J20) -> -6253.3387 | K27: =J27*(1+K20) -> -6669.0743 | L27: =K27*(1+L20) -> -7112.449 | M27: =L27*(1+M20) -> -7585.3002
C29: Memo: Amortization in opex and COGS | D29: 0 | E29: 0 | F29: 0 | G29: 0 | H29: 0 | I29: =H29 -> 0 | J29: =I29 -> 0 | K29: =J29 -> 0 | L29: =K29 -> 0 | M29: =L29 -> 0
C30: Memo: Purchases of Intangibles | D30: 0 | E30: 0 | F30: 0 | G30: 0 | H30: 0 | I30: =H30 -> 0 | J30: =I30 -> 0 | K30: =J30 -> 0 | L30: =K30 -> 0 | M30: =L30 -> 0
C32: Memo: % Interest Earned on Debt | E32: =E12/((SUM(D58:D59)+SUM(E58:E59))/2) -> -0.023982999 | F32: =F12/((SUM(E58:E59)+SUM(F58:F59))/2) -> -0.026979175 | G32: =G12/((SUM(F58:F59)+SUM(G58:G59))/2) -> -0.030256915 | H32: =H12/((SUM(G58:G59)+SUM(H58:H59))/2) -> -0.026766316 | I32: =AVERAGE(G32:H32) -> -0.028511616 | J32: =I32 -> -0.028511616 | K32: =J32 -> -0.028511616 | L32: =K32 -> -0.028511616 | M32: =L32 -> -0.028511616
C33: Memo: % Interest Earned on Cash | E33: =E11/((SUM(D37:D38)+SUM(E37:E38))/2) -> 0.017654151 | F33: =F11/((SUM(E37:E38)+SUM(F37:F38))/2) -> 0.040558536 | G33: =G11/((SUM(F37:F38)+SUM(G37:G38))/2) -> 0.047312154 | H33: =H11/((SUM(G37:G38)+SUM(H37:H38))/2) -> 0.044573937 | I33: =AVERAGE(G33:H33) -> 0.045943045 | J33: =I33 -> 0.045943045 | K33: =J33 -> 0.045943045 | L33: =K33 -> 0.045943045 | M33: =L33 -> 0.045943045
B35: x | C35: Balance Sheet
C37: Cash and Equivalents | D37: 11258 | E37: 10203 | F37: 13700 | G37: 9906 | H37: 14161 | I37: =I70-SUM(I38:I41)-I47 -> 19289.828 | J37: =J70-SUM(J38:J41)-J47 -> 25546.721 | K37: =K70-SUM(K38:K41)-K47 -> 32671.799 | L37: =L70-SUM(L38:L41)-L47 -> 40828.306 | M37: =M70-SUM(M38:M41)-M47 -> 50251.401
C38: Short Term Investments | D38: 917 | E38: 846 | F38: 1534 | G38: 1238 | H38: 1123 | I38: =AVERAGE(F38:H38) -> 1298.3333 | J38: =AVERAGE(G38:I38) -> 1219.7778 | K38: =AVERAGE(H38:J38) -> 1213.7037 | L38: =AVERAGE(I38:K38) -> 1243.9383 | M38: =AVERAGE(J38:L38) -> 1225.8066
C39: Accounts Receivable | D39: 1803 | E39: 2241 | F39: 2285 | G39: 2721 | H39: 3203 | I39: =H39*(1+I20) -> 3415.9425 | J39: =I39*(1+J20) -> 3643.0418 | K39: =J39*(1+K20) -> 3885.2392 | L39: =K39*(1+L20) -> 4143.5384 | M39: =L39*(1+M20) -> 4419.0099
C40: Inventory | D40: 14215 | E40: 17907 | F40: 16651 | G40: 18647 | H40: 18116 | I40: =H40*(1+I24) -> 19345.87 | J40: =I40*(1+J24) -> 20632.026 | K40: =J40*(1+K24) -> 22003.688 | L40: =K40*(1+L24) -> 23466.542 | M40: =L40*(1+M24) -> 25026.649
C41: Prepaid Expenses and other WC Assets | D41: 1312 | E41: 1499 | F41: 1709 | G41: 1734 | H41: 1777 | I41: =H41*(1+I22) -> 1937.2421 | J41: =I41*(1+J22) -> 2111.934 | K41: =J41*(1+K22) -> 2302.379 | L41: =K41*(1+L22) -> 2509.9974 | M41: =L41*(1+M22) -> 2736.3379
C42: Current Assets | D42: =SUM(D37:D41) -> 29505 | E42: =SUM(E37:E41) -> 32696 | F42: =SUM(F37:F41) -> 35879 | G42: =SUM(G37:G41) -> 34246 | H42: =SUM(H37:H41) -> 38380 | I42: =SUM(I37:I41) -> 45287.216 | J42: =SUM(J37:J41) -> 53153.5 | K42: =SUM(K37:K41) -> 62076.809 | ... M42: =SUM(M37:M41) -> 83659.204
C44: Property plants and equipment | D44: 23492 | E44: 24646 | F44: 26684 | G44: 29032 | H44: 31909 | I44: =H44-I27+I26 -> 35185.233 | J44: =I44-J27+J26 -> 38679.278 | K44: =J44-K27+K26 -> 42405.614 | L44: =K44-L27+L26 -> 46379.685 | M44: =L44-M27+M26 -> 50617.961
C45: Operating lease ROU assets | D45: 2890 | E45: 2774 | F45: 2713 | G45: 2617 | H45: 2725 | I45: =H45 -> 2725 | J45: =I45 -> 2725 | K45: =J45 -> 2725 | L45: =K45 -> 2725 | M45: =L45 -> 2725
C46: Other long-term assets | D46: 3381 | E46: 4050 | F46: 3718 | G46: 3936 | H46: 4085 | I46: =H46-I30+I29 -> 4085 | J46: =I46-J30+J29 -> 4085 | K46: =J46-K30+K29 -> 4085 | L46: =K46-L30+L29 -> 4085 | M46: =L46-M30+M29 -> 4085
C47: Non Current Assets | D47: =SUM(D44:D46) -> 29763 | E47: =SUM(E44:E46) -> 31470 | F47: =SUM(F44:F46) -> 33115 | G47: =SUM(G44:G46) -> 35585 | H47: =SUM(H44:H46) -> 38719 | I47: =SUM(I44:I46) -> 41995.233 | J47: =SUM(J44:J46) -> 45489.278 | K47: =SUM(K44:K46) -> 49215.614 | ... M47: =SUM(M44:M46) -> 57427.961
C49: Total Assets | D49: =D42+D47 -> 59268 | E49: =E42+E47 -> 64166 | F49: =F42+F47 -> 68994 | G49: =G42+G47 -> 69831 | H49: =H42+H47 -> 77099 | I49: =I42+I47 -> 87282.449 | J49: =J42+J47 -> 98642.778 | K49: =K42+K47 -> 111292.42 | ... M49: =M42+M47 -> 141087.17
C51: Acounts Payable | D51: 16278 | E51: 17848 | F51: 17483 | G51: 19421 | H51: 19783 | I51: =H51*(1+I20) -> 21098.217 | J51: =I51*(1+J20) -> 22500.873 | K51: =J51*(1+K20) -> 23996.78 | L51: =K51*(1+L20) -> 25592.139 | M51: =L51*(1+M20) -> 27293.56
C52: Accrued salaries and benefits | D52: 4090 | E52: 4381 | F52: 4278 | G52: 4794 | H52: 5205 | I52: =H52*(1+I21) -> 5867.5064 | J52: =I52*(1+J21) -> 6614.3384 | K52: =J52*(1+K21) -> 7456.2292 | L52: =K52*(1+L21) -> 8405.2781 | M52: =L52*(1+M21) -> 9475.1245
C53: Accrued membership rewards | D53: 1671 | E53: 1911 | F53: 2150 | G53: 2435 | H53: 2677 | I53: =H53*(1+I22) -> 2918.4001 | J53: =I53*(1+J22) -> 3181.5686 | K53: =J53*(1+K22) -> 3468.4685 | L53: =K53*(1+L22) -> 3781.2397 | M53: =L53*(1+M22) -> 4122.2153
...

Sheet DCF
A1: x
B2: COSTCO DCF
B4: Ticker: | C4: #VALUE! | E4: Implied Price | G4: =N83 -> 426.11016 | I4: Implied Upside (Downside) | L4: =G4/G5-1 -> -0.54681185
B5: Date: | C5: =TODAY() -> 46054 | E5: Current Price | G5: {=_FV(C4,"price")} -> 940.25
A7: x | B7: Assumptions
B8: Switches | F8: Conservative | J8: Street / Base | N8: Optimistic
B9: Master | D9: 3 | F9: Revenue 2027 | H9: 0.9 | N9: Revenue 2027 | P9: 1.1
B10: Revenue | D10: =D9 -> 3 | F10: Revenue 2030 | H10: 0.04 | J10: Revenue 2030 | L10: 0.05 | N10: Revenue 2030 | P10: 0.06
B11: EBIT | D11: =D10 -> 3 | F11: EBIT 2027 | H11: 0.95 | N11: EBIT 2027 | P11: 1.05
B12: WACC | D12: =D11 -> 3 | F12: EBIT 2030 | H12: 0.037 | J12: EBIT 2030 | L12: 0.04 | N12: EBIT 2030 | P12: 0.043
B13: TGR | D13: =D12 -> 3 | F13: WACC | H13: =L13+0.5% -> 0.078448391 | J13: WACC | L13: =WACC!D22 -> 0.073448391 | N13: WACC | P13: =L13-0.05% -> 0.072948391
F14: TGR | H14: =L14-0.005 -> 0.025 | J14: TGR | L14: 0.03 | N14: TGR | P14: =L14+0.005 -> 0.035
B15: WACC | D15: =CHOOSE(D12,H13,L13,P13) -> 0.072948391
B16: TGR | D16: =CHOOSE(D13,H14,L14,P14) -> 0.035
A19: x | B19: Income Statement | E19: 2021 | F19: 2022 | G19: 2023 | H19: 2024 | I19: 2025 | J19: 2026 | K19: 2027 | L19: 2028 | M19: 2029 | N19: 2030
B20: Revenue | E20: ='3_Statement_Model'!D6 -> 195929 | F20: ='3_Statement_Model'!E6 -> 226954 | G20: ='3_Statement_Model'!F6 -> 242290 | H20: ='3_Statement_Model'!G6 -> 254453 | I20: ='3_Statement_Model'!H6 -> 275235 | J20: ='3_Statement_Model'!I6 -> 293533.23 | K20: ='3_Statement_Model'!J6 -> 313047.96 | L20: ='3_Statement_Model'!K6 -> 333860.07 | ... N20: ='3_Statement_Model'!M6 -> 379727.19
B21: % growth | F21: =F20/E20-1 -> 0.15834818 | G21: =G20/F20-1 -> 0.067573165 | H21: =H20/G20-1 -> 0.050200173 | I21: =I20/H20-1 -> 0.081673236 | J21: =J20/I20-1 -> 0.066482191 | K21: =K20/J20-1 -> 0.066482191 | L21: =L20/K20-1 -> 0.066482191 | M21: =M20/L20-1 -> 0.066482191 | N21: =N20/M20-1 -> 0.066482191
B23: EBIT | E23: ='3_Statement_Model'!D9 -> 6708 | F23: ='3_Statement_Model'!E9 -> 7793 | G23: ='3_Statement_Model'!F9 -> 8114 | H23: ='3_Statement_Model'!G9 -> 9285 | I23: ='3_Statement_Model'!H9 -> 10383 | J23: ='3_Statement_Model'!I9 -> 10892.162 | K23: ='3_Statement_Model'!J9 -> 11616.297 | L23: ='3_Statement_Model'!K9 -> 12388.573 | ... N23: ='3_Statement_Model'!M9 -> 14090.568
B24: % of sales | E24: =E23/E20 -> 0.034236892 | F24: =F23/F20 -> 0.034337355 | G24: =G23/G20 -> 0.033488794 | H24: =H23/H20 -> 0.036490039 | I24: =I23/I20 -> 0.037724127 | J24: =J23/J20 -> 0.037107083 | K24: =K23/K20 -> 0.037107083 | L24: =L23/L20 -> 0.037107083 | ... N24: =N23/N20 -> 0.037107083
B26: Taxes | E26: ='3_Statement_Model'!D15 -> -1601 | F26: ='3_Statement_Model'!E15 -> -1925 | G26: ='3_Statement_Model'!F15 -> -2195 | H26: ='3_Statement_Model'!G15 -> -2373 | I26: ='3_Statement_Model'!H15 -> -2719 | J26: ='3_Statement_Model'!I15 -> -2858.6461 | K26: ='3_Statement_Model'!J15 -> -3099.7418 | L26: ='3_Statement_Model'!K15 -> -3365.9499 | ... N26: ='3_Statement_Model'!M15 -> -3969.8588
B27: % of EBIT | E27: =E26/E23 -> -0.23867024 | F27: =F26/F23 -> -0.24701655 | G27: =G26/G23 -> -0.27052009 | H27: =H26/H23 -> -0.25557351 | I27: =I26/I23 -> -0.26187037 | J27: =J26/J23 -> -0.26244984 | K27: =K26/K23 -> -0.26684424 | L27: =L26/L23 -> -0.27169794 | ... N27: =N26/N23 -> -0.28173872
A29: x | B29: Cash Flow Items | E29: 2021 | F29: 2022 | G29: 2023 | H29: 2024 | I29: 2025 | J29: 2026 | K29: 2027 | L29: 2028 | M29: 2029 | N29: 2030
B30: Depreciation & Amortization | E30: ='3_Statement_Model'!D26+'3_Statement_Model'!D29 -> -1781 | F30: ='3_Statement_Model'!E26+'3_Statement_Model'!E29 -> -1900 | G30: ='3_Statement_Model'!F26+'3_Statement_Model'!F29 -> -2077 | H30: ='3_Statement_Model'!G26+'3_Statement_Model'!G29 -> -2237 | I30: ='3_Statement_Model'!H26+'3_Statement_Model'!H29 -> -2426 | J30: ='3_Statement_Model'!I26+'3_Statement_Model'!I29 -> -2587.2858 | K30: ='3_Statement_Model'!J26+'3_Statement_Model'!J29 -> -2759.2942 | L30: ='3_Statement_Model'!K26+'3_Statement_Model'!K29 -> -2942.7382 | ... N30: ='3_Statement_Model'!M26+'3_Statement_Model'!M29 -> -3347.0241
B31: % of sales | E31: =E30/E20 -> -0.0090900275 | F31: =F30/F20 -> -0.0083717405 | G31: =G30/G20 -> -0.008572372 | H31: =H30/H20 -> -0.0087914075 | I31: =I30/I20 -> -0.008814286 | J31: =J30/J20 -> -0.008814286 | K31: =K30/K20 -> -0.008814286 | L31: =L30/L20 -> -0.008814286 | ... N31: =N30/N20 -> -0.008814286
B32: % of capital expenditures | E32: =E30/E34 -> 0.49637681 | F32: =F30/F34 -> 0.48830635 | G32: =G30/G34 -> 0.48045339 | H32: =H30/H34 -> 0.47494692 | I32: =I30/I34 -> 0.44125136 | J32: =J30/J34 -> 0.44125136 | K32: =K30/K34 -> 0.44125136 | L32: =L30/L34 -> 0.44125136 | ... N32: =N30/N34 -> 0.44125136
B34: Capital Expenditures | E34: ='3_Statement_Model'!D27 -> -3588 | F34: ='3_Statement_Model'!E27 -> -3891 | G34: ='3_Statement_Model'!F27 -> -4323 | H34: ='3_Statement_Model'!G27 -> -4710 | I34: ='3_Statement_Model'!H27 -> -5498 | J34: ='3_Statement_Model'!I27 -> -5863.5191 | K34: ='3_Statement_Model'!J27 -> -6253.3387 | L34: ='3_Statement_Model'!K27 -> -6669.0743 | ... N34: ='3_Statement_Model'!M27 -> -7585.3002
B35: % of sales | E35: =E34/E20 -> -0.018312756 | F35: =F34/F20 -> -0.017144443 | G35: =G34/G20 -> -0.017842255 | H35: =H34/H20 -> -0.018510295 | I35: =I34/I20 -> -0.019975657 | J35: =J34/J20 -> -0.019975657 | K35: =K34/K20 -> -0.019975657 | L35: =L34/L20 -> -0.019975657 | ... N35: =N34/N20 -> -0.019975657
B37: Change in Net Working Capital | E37: ='3_Statement_Model'!D93 -> 1003 | F37: ='3_Statement_Model'!E93 -> -1563 | G37: ='3_Statement_Model'!F93 -> 1018 | H37: ='3_Statement_Model'!G93 -> 611 | I37: ='3_Statement_Model'!H93 -> 1764
B38: % of sales | E38: =E37/E20 -> 0.0051192013 | F38: =F37/F20 -> -0.0068868581 | G38: =G37/G20 -> 0.0042015766 | H38: =H37/H20 -> 0.0024012293 | I38: =I37/I20 -> 0.0064090686
B39: % change in sales | F39: =(F37-E37)/(F20-E20) -> -0.082707494 | G39: =(G37-F37)/(G20-F20) -> 0.16829682 | H39: =(H37-G37)/(H20-G20) -> -0.033462139 | I39: =(I37-H37)/(I20-H20) -> 0.055480704
A41: x | B41: DCF | E41: 2021 | F41: 2022 | G41: 2023 | H41: 2024 | I41: 2025 | J41: 2026 | K41: 2027 | L41: 2028 | M41: 2029 | N41: 2030
B42: Revenue | E42: =E20 -> 195929 | F42: =F20 -> 226954 | G42: =G20 -> 242290 | H42: =H20 -> 254453 | I42: =I20 -> 275235 | J42: =I42*(1+J43) -> 293533.23 | K42: =J42*(1+K43) -> 314197.97 | L42: =K42*(1+L43) -> 335228.28 | M42: =L42*(1+M43) -> 356504.1 | N42: =M42*(1+N43) -> 377894.35
B43: % growth | F43: =F20/E20-1 -> 0.15834818 | G43: =G20/F20-1 -> 0.067573165 | H43: =H20/G20-1 -> 0.050200173 | I43: =I20/H20-1 -> 0.081673236 | J43: =OFFSET(J43,$D$10,0) -> 0.066482191 | K43: =OFFSET(K43,$D$10,0) -> 0.0704 | L43: =OFFSET(L43,$D$10,0) -> 0.066933333 | M43: =OFFSET(M43,$D$10,0) -> 0.063466667 | N43: =OFFSET(N43,$D$10,0) -> 0.06
B44: Conservative Case | J44: =J45 -> 0.066482191 | K44: =K45*$H$9 -> 0.0576 | L44: =$N$44+($K$44-$N$44)*((L41-$N$41)/($K$41-$N$41)) -> 0.051733333 | M44: =$N$44+($K$44-$N$44)*((M41-$N$41)/($K$41-$N$41)) -> 0.045866667 | N44: =H10 -> 0.04
B45: Street (Base) Case | J45: =J21 -> 0.066482191 | K45: 0.064 | L45: =$N$45+($K$45-$N$45)*((L41-$N$41)/($K$41-$N$41)) -> 0.059333333 | M45: =$N$45+($K$45-$N$45)*((M41-$N$41)/($K$41-$N$41)) -> 0.054666667 | N45: 0.05
B46: Optimistic Case | J46: =J45 -> 0.066482191 | K46: =K45*$P$9 -> 0.0704 | L46: =$N$46+($K$46-$N$46)*((L41-$N$41)/($K$41-$N$41)) -> 0.066933333 | M46: =$N$46+($K$46-$N$46)*((M41-$N$41)/($K$41-$N$41)) -> 0.063466667 | N46: =P10 -> 0.06
B48: EBIT | E48: =E23 -> 6708 | F48: =F23 -> 7793 | G48: =G23 -> 8114 | H48: =H23 -> 9285 | I48: =I23 -> 10383 | J48: =J42*J49 -> 10892.162 | K48: =K42*K49 -> 12241.918 | L48: =L42*L49 -> 13512.479 | M48: =M42*M49 -> 14689.94 | N48: =N42*N49 -> 16249.457
B49: % of sales | E49: =E48/E42 -> 0.034236892 | F49: =F48/F42 -> 0.034337355 | G49: =G48/G42 -> 0.033488794 | H49: =H48/H42 -> 0.036490039 | I49: =I48/I42 -> 0.037724127 | J49: =OFFSET(J49,$D$11,0) -> 0.037107083 | K49: =OFFSET(K49,$D$11,0) -> 0.038962437 | L49: =OFFSET(L49,$D$11,0) -> 0.040308291 | M49: =OFFSET(M49,$D$11,0) -> 0.041205528 | N49: =OFFSET(N49,$D$11,0) -> 0.043
B50: Conservative Case | J50: =J51 -> 0.037107083 | K50: =J50*H11 -> 0.035251729 | L50: =K50+($N$50-K50)/($N$41-$K$41) -> 0.035834486 | M50: =L50+($N$50-L50)/($N$41-$K$41) -> 0.036222991 | N50: =H12 -> 0.037
B51: Street (Base) Case | J51: =J24 -> 0.037107083 | K51: =K24 -> 0.037107083 | L51: =K51+($N$51-K51)/($N$41-$K$41) -> 0.038071389 | M51: =L51+($N$51-L51)/($N$41-$K$41) -> 0.038714259 | N51: 0.04
...

Sheet WACC
B2: WACC
A4: x | B4: WACC
B6: WACC = (% Equity x Cost of Equity) + (% Debt x Cost of Debt x (1 -Tax rate))
B8: Market Cap | D8: 423.04
B9: % of Equity | D9: =D8/D20 -> 0.98650275
B10: Cost of Equity | D10: 0.0743
B11: Risk Free Rate | D11: 0.04269
B12: Beta | D12: 1.01
B13: Market Risk Premium | D13: 0.0418
B15: Debt | D15: =0.075+5.713 -> 5.788
B16: % of Debt | D16: =D15/D8 -> 0.013681921
B17: Cost of Debt | D17: =154/10383 -> 0.014831937
B18: Tax Rate | D18: =-DCF!J56 -> 0.25473015
B20: Total | D20: =D8+D15 -> 428.828
A22: x | B22: WACC | D22: =(D9*D10)+(D16*D17*(1-D18)) -> 0.073448391
